{ 
  "text" : "The urllib3 library before 1.24.2 for Python mishandles certain cases where the desired set of CA certificates is different from the OS store of CA certificates, which results in SSL connections succeeding in situations where a verification failure is the correct outcome. This is related to use of the ssl_context, ca_certs, or ca_certs_dir argument.\n" ,
  "entities" : [ { 
    "eid" : "E1" ,
    "keyid" : "Identity#5435c69ed3bcc5b2e4d580e393e373d3" ,
    "type" : "Identity" ,
    "subType" : "Organization" ,
    "value" : "ca" ,
    "begin" : 95 ,
    "end" : 97 ,
    "canonicalForm" : "CA" ,
    "score" : "0.0"
  }
  , { 
    "eid" : "E2" ,
    "keyid" : "Identity#5435c69ed3bcc5b2e4d580e393e373d3" ,
    "type" : "Identity" ,
    "subType" : "Organization" ,
    "value" : "ca" ,
    "begin" : 145 ,
    "end" : 147 ,
    "canonicalForm" : "CA" ,
    "score" : "0.0"
  }
  ,  ] ,
  "relations" : [  ]
}
